Watching for file changes with StatReloader
Exception in thread django-main-thread:
Traceback (most recent call last):
  File "/usr/lib64/python3.9/threading.py", line 954, in _bootstrap_inner
    self.run()
  File "/usr/lib64/python3.9/threading.py", line 892, in run
    self._target(*self._args, **self._kwargs)
  File "/home/vagrant/.local/share/virtualenvs/vagrant-gKDsaKU3/lib/python3.9/site-packages/django/utils/autoreload.py", line 64, in wrapper
    fn(*args, **kwargs)
  File "/home/vagrant/.local/share/virtualenvs/vagrant-gKDsaKU3/lib/python3.9/site-packages/django/core/management/commands/runserver.py", line 134, in inner_run
    self.check(display_num_errors=True)
  File "/home/vagrant/.local/share/virtualenvs/vagrant-gKDsaKU3/lib/python3.9/site-packages/django/core/management/base.py", line 475, in check
    all_issues = checks.run_checks(
  File "/home/vagrant/.local/share/virtualenvs/vagrant-gKDsaKU3/lib/python3.9/site-packages/django/core/checks/registry.py", line 88, in run_checks
    new_errors = check(app_configs=app_configs, databases=databases)
  File "/home/vagrant/.local/share/virtualenvs/vagrant-gKDsaKU3/lib/python3.9/site-packages/django/core/checks/urls.py", line 14, in check_url_config
    return check_resolver(resolver)
  File "/home/vagrant/.local/share/virtualenvs/vagrant-gKDsaKU3/lib/python3.9/site-packages/django/core/checks/urls.py", line 24, in check_resolver
    return check_method()
  File "/home/vagrant/.local/share/virtualenvs/vagrant-gKDsaKU3/lib/python3.9/site-packages/django/urls/resolvers.py", line 494, in check
    for pattern in self.url_patterns:
  File "/home/vagrant/.local/share/virtualenvs/vagrant-gKDsaKU3/lib/python3.9/site-packages/django/utils/functional.py", line 57, in __get__
    res = instance.__dict__[self.name] = self.func(instance)
  File "/home/vagrant/.local/share/virtualenvs/vagrant-gKDsaKU3/lib/python3.9/site-packages/django/urls/resolvers.py", line 715, in url_patterns
    patterns = getattr(self.urlconf_module, "urlpatterns", self.urlconf_module)
  File "/home/vagrant/.local/share/virtualenvs/vagrant-gKDsaKU3/lib/python3.9/site-packages/django/utils/functional.py", line 57, in __get__
    res = instance.__dict__[self.name] = self.func(instance)
  File "/home/vagrant/.local/share/virtualenvs/vagrant-gKDsaKU3/lib/python3.9/site-packages/django/urls/resolvers.py", line 708, in urlconf_module
    return import_module(self.urlconf_name)
  File "/usr/lib64/python3.9/importlib/__init__.py", line 127, in import_module
    return _bootstrap._gcd_import(name[level:], package, level)
  File "<frozen importlib._bootstrap>", line 1030, in _gcd_import
  File "<frozen importlib._bootstrap>", line 1007, in _find_and_load
  File "<frozen importlib._bootstrap>", line 986, in _find_and_load_unlocked
  File "<frozen importlib._bootstrap>", line 680, in _load_unlocked
  File "<frozen importlib._bootstrap_external>", line 790, in exec_module
  File "<frozen importlib._bootstrap>", line 228, in _call_with_frames_removed
  File "/vagrant/beyond_tutorial/urls.py", line 18, in <module>
    from msgboard import views
  File "/vagrant/msgboard/views.py", line 3, in <module>
    from .forms import MessageForm
  File "/vagrant/msgboard/forms.py", line 4
    class MessageForm(forms.ModelForm):
IndentationError: unexpected indent
